//! Exception module
//!
//! In Dragon Bot Z, an Exception is a recoverable error, you should not panic
//! after catching an Exception, but instead, you may catch it and go on.
//!
//! Authors: Lahc√®ne Belhadi <lahcene.belhadi@gmail.com>

use core::fmt;

// Custom Result type containing an exception
pub type ExcResult<T> = std::result::Result<T, Exception>;

/// Recoverable errors
#[derive(Debug)]
pub enum Exception {
    InsertNewCharacter(String),
    RetrieveCharacter(String),
    RetrieveMultipleCharacters(String),
}

impl fmt::Display for Exception {
    fn fmt(&self, f: &mut fmt::Formatter<'_>) -> fmt::Result {
        let content = match &self {
            Exception::InsertNewCharacter(error) => format!("[Exception][Insert New Character] An error occured while trying to add a new character to the database: {error}"),
            Exception::RetrieveCharacter(error) => format!("[Exception][Retrieve Character] An error occured while trying to retrieve a character from the database: {error}"),
            Exception::RetrieveMultipleCharacters(error) => format!("[Exception][Retrieve Multiple Characters] An error occured while trying to retrieve multiple characters from database: {error}"),
        };

        write!(f, "{}", content)
    }
}
